import { nextTestSetup } from 'e2e-utils'
import { retry } from 'next-test-utils'

describe('on-request-error - server-action-error', () => {
  const { next, skipped } = nextTestSetup({
    files: __dirname,
    skipDeployment: true,
    env: {
      __NEXT_EXPERIMENTAL_INSTRUMENTATION: '1',
    },
  })

  if (skipped) {
    return
  }

  const outputLogPath = 'output-log.json'

  async function getOutputLogJson() {
    if (!(await next.hasFile(outputLogPath))) {
      return {}
    }
    const content = await next.readFile(outputLogPath)
    return JSON.parse(content)
  }

  async function validateErrorRecord({
    errorMessage,
    url,
  }: {
    errorMessage: string
    url: string
  }) {
    // Assert the instrumentation is called
    await retry(async () => {
      const recordLogs = next.cliOutput
        .split('\n')
        .filter((log) => log.includes('[instrumentation] write-log'))
      const expectedLog = recordLogs.find((log) => log.includes(errorMessage))
      expect(expectedLog).toBeDefined()
    }, 5000)

    const json = await getOutputLogJson()
    const record = json[errorMessage]

    // Assert error is recorded in the output log
    expect(record).toMatchObject({
      payload: {
        message: errorMessage,
        request: {
          url,
          method: 'POST',
          headers: expect.objectContaining({
            accept: 'text/x-component',
          }),
        },
        context: {
          routerKind: 'App Router',
          routeType: 'action',
          renderSource: 'react-server-components-payload',
        },
      },
      count: 1,
    })
  }

  beforeAll(async () => {
    await next.patchFile(outputLogPath, '{}')
  })

  it('should catch server action error in listener callback in nodejs runtime', async () => {
    const browser = await next.browser('/client/callback')
    await browser.elementByCss('button').click()

    await validateErrorRecord({
      errorMessage: '[server-action]:callback',
      url: '/client/callback',
    })
  })

  it('should catch server action error in listener callback in edge runtime', async () => {
    const browser = await next.browser('/client/callback/edge')
    await browser.elementByCss('button').click()

    await validateErrorRecord({
      errorMessage: '[server-action]:callback:edge',
      url: '/client/callback/edge',
    })
  })

  it('should catch the server action form error in nodejs runtime', async () => {
    const browser = await next.browser('/form-error')
    await browser.elementByCss('button').click()

    await validateErrorRecord({
      errorMessage: '[server-action]:form',
      url: '/form-error',
    })
  })

  it('should catch the server action form error in edge runtime', async () => {
    const browser = await next.browser('/form-error/edge')
    await browser.elementByCss('button').click()

    await validateErrorRecord({
      errorMessage: '[server-action]:form:edge',
      url: '/form-error/edge',
    })
  })
})
